#VRML_SIM R2020a utf8
WorldInfo {
  contactProperties [
    ContactProperties {
    }
  ]
}
Viewpoint {
  orientation -0.0875990624494794 0.980703118317722 0.17477928361184178 2.2466562529348524
  position 0.7432062717212379 0.6082290495325758 -0.6255767589446035
}
TexturedBackground {
}
TexturedBackgroundLight {
}
RectangleArena {
  floorSize 2 2
  floorTileSize 4 2
}
Robot {
  children [
    DEF ROBOT Group {
      children [
        DEF BOX Transform {
          translation 0 0.2828 0
          rotation 0 0 1 0.7853
          children [
            Shape {
              appearance PBRAppearance {
                roughness 1
              }
              geometry Box {
                size 0.4 0.4 0.1
              }
            }
          ]
        }
        HingeJoint {
          jointParameters HingeJointParameters {
            axis 0 0 1
            anchor 0 0.4 0
          }
          device [
            RotationalMotor {
              name "steer"
              maxVelocity 15
              minPosition -0.7854
              maxPosition 0.7854
              maxTorque 1000
            }
          ]
          endPoint Solid {
            translation 0 0.4 -0.1
            rotation -1 0 0 1.5699999999999994
            children [
              Group {
                children [
                  Solid {
                    children [
                      DEF Topcylinder Shape {
                        appearance PBRAppearance {
                          baseColor 0.109804 0.109804 0.109804
                          roughness 1
                          metalness 0
                        }
                        geometry Cylinder {
                          height 0.1
                          radius 0.03
                        }
                      }
                    ]
                    name "solid(1)"
                    boundingObject USE Topcylinder
                  }
                  Solid {
                    translation 0 0 -0.12
                    rotation 1 0 0 -1.57
                    children [
                      DEF String Shape {
                        appearance DEF Metal PBRAppearance {
                          roughness 1
                          metalness 0.2
                        }
                        geometry Cylinder {
                          height 0.18
                          radius 0.004
                        }
                      }
                    ]
                    boundingObject USE String
                  }
                  Solid {
                    translation 0 0 -0.22
                    rotation 1 0 0 0
                    children [
                      DEF Weight Shape {
                        appearance PBRAppearance {
                        }
                        geometry Sphere {
                          radius 0.05
                        }
                      }
                    ]
                    name "solid(2)"
                    boundingObject USE Weight
                    physics Physics {
                      density -1
                      mass 10
                    }
                  }
                ]
              }
            ]
            name "solid(3)"
          }
        }
      ]
    }
  ]
  boundingObject USE BOX
  physics Physics {
  }
  controller "Triangle_Controller"
}
