#VRML_SIM R2020a utf8
WorldInfo {
}
Viewpoint {
  orientation -0.09250765394036684 0.9847458336633794 0.14737020406128729 1.992400731647192
  position 0.8561633583575834 0.4383978451484237 -0.35561741138321057
}
TexturedBackground {
}
TexturedBackgroundLight {
}
RectangleArena {
  floorSize 2 2
  floorTileSize 4 2
}
Robot {
  children [
    DEF Shape Group {
      children [
        Transform {
          translation 0 0.02 0.28
          rotation 1 0 0 -1.5707953071795862
          children [
            Solid {
              children [
                DEF Wheel Shape {
                  appearance DEF Rubber PBRAppearance {
                    baseColor 0.235294 0.235294 0.235294
                    roughness 1
                    metalness 0
                  }
                  geometry Cylinder {
                    height 0.06
                    radius 0.02
                  }
                }
              ]
            }
          ]
        }
        Transform {
          translation 0 0.02 -0.28
          rotation 1 0 0 -1.5707953071795862
          children [
            Solid {
              children [
                USE Wheel
              ]
              name "solid(1)"
            }
          ]
        }
        Transform {
          translation 0 0.27 0.03
          scale 1.0236846583009844 1.009333379401268 1
          children [
            DEF TopBox Shape {
              appearance DEF Metal PBRAppearance {
                roughness 1
                metalness 0.2
              }
              geometry Box {
                size 0.03 0.02 0.04
              }
            }
          ]
        }
        Transform {
          translation 0 0.27 -0.03
          scale 1.0236846583009844 1.009333379401268 1
          children [
            USE TopBox
          ]
        }
        Transform {
          translation 0 0.149438 0.167442
          rotation -1 0 0 -0.7854053071795866
          children [
            DEF SupportBox Shape {
              appearance USE Metal
              geometry Box {
                size 0.03 0.02 0.35
              }
            }
          ]
        }
        Transform {
          translation 0 0.149438 -0.167442
          rotation 1 0 0 -0.7854053071795866
          children [
            USE SupportBox
          ]
        }
        HingeJoint {
          jointParameters HingeJointParameters {
            axis 0 0 1
            anchor 0 0.27 0
          }
          device [
            RotationalMotor {
              name "steer"
              maxVelocity 15
              minPosition -0.7854
              maxPosition 0.7854
            }
          ]
          endPoint Solid {
            translation 0 0.27 0
            rotation -1 0 0 1.57
            children [
              Group {
                children [
                  Solid {
                    children [
                      DEF Topcylinder Shape {
                        appearance PBRAppearance {
                          baseColor 0.109804 0.109804 0.109804
                          roughness 1
                          metalness 0
                        }
                        geometry Cylinder {
                          height 0.02
                          radius 0.03
                        }
                      }
                    ]
                    name "solid(1)"
                  }
                  Solid {
                    translation 0 0 -0.12
                    rotation 1 0 0 -1.57
                    children [
                      DEF String Shape {
                        appearance USE Metal
                        geometry Cylinder {
                          height 0.18
                          radius 0.004
                        }
                      }
                    ]
                  }
                  Solid {
                    translation 0 0 -0.22
                    rotation 1 0 0 0
                    children [
                      DEF Weight Shape {
                        appearance PBRAppearance {
                          baseColor 0 0.666667 0
                          roughness 1
                          metalness 0
                        }
                        geometry Capsule {
                          height 0.05
                          radius 0.03
                        }
                      }
                    ]
                    name "solid(2)"
                  }
                ]
              }
            ]
            name "solid(3)"
          }
        }
      ]
    }
  ]
  controller "Triangle_Controller"
}
